<mujoco model="quaid">
    <compiler inertiafromgeom="true" angle="degree" coordinate="local"/>
    <option timestep="0.005" gravity="0 0 -9.81" iterations="20" integrator="RK4" >
        <!-- this was deprecated in 3.14 - you need to add your own noise now -->
        <flag sensornoise="enable" />
    </option>


    <asset>
        <texture type="skybox" builtin="gradient" rgb1="0.3 0.5 0.7" rgb2="0 0 0" width="512" height="3072"/>
        <texture type="2d" name="groundplane" builtin="checker" mark="edge" rgb1="0.2 0.3 0.4"
                 rgb2="0.1 0.2 0.3" markrgb="0.8 0.8 0.8" width="300" height="300"/>
        <material name="groundplane" texture="groundplane" texuniform="true" texrepeat="5 5" reflectance="0.2"/>

        <mesh file="left_calf.stl" scale="1 1 1" />
        <mesh file="left_knee_horn.stl" scale="1 1 1" />
        <mesh file="left_knee_link.stl" scale="1 1 1" />
        <mesh file="left_thigh_servo.stl" scale="1 1 1" />
        <mesh file="left_knee_servo.stl" scale="1 1 1" />
        <mesh file="left_servo_mount.stl" scale="1 1 1" />
        <mesh file="left_thigh.stl" scale="1 1 1" />
        <mesh file="left_thigh_horn.stl" scale="1 1 1" />
        <mesh file="left_thigh_link.stl" scale="1 1 1" />
        <mesh file="right_calf.stl" scale="1 1 1" />
        <mesh file="right_knee_horn.stl" scale="1 1 1" />
        <mesh file="right_knee_link.stl" scale="1 1 1" />
        <mesh file="right_thigh_servo.stl" scale="1 1 1" />
        <mesh file="right_knee_servo.stl" scale="1 1 1" />
        <mesh file="right_servo_mount.stl" scale="1 1 1" />
        <mesh file="right_thigh.stl" scale="1 1 1" />
        <mesh file="right_thigh_horn.stl" scale="1 1 1" />
        <mesh file="right_thigh_link.stl" scale="1 1 1" />
        <mesh file="pelvis.stl" scale="1 1 1" />
        <mesh file="fuselage.stl" scale="1 1 1" />
    </asset>




    <default>
        <joint armature="1" damping="1" limited="true"/>
        <geom conaffinity="0" condim="3" density="300.0" margin="0.002" /> <!-- rgba="0.8 0.6 0.4 1" -->
        <!--         <geom friction=".1 .1 .1" density="300" margin="0.002" condim="1" contype="0" conaffinity="0"/>-->

        <default class="collision">
            <geom contype="1" group="3" type="capsule"/>
            <default class="collision-left">
                <geom contype="2" conaffinity="4"/>
            </default>
            <default class="collision-right">
                <geom contype="4" conaffinity="2"/>
            </default>
        </default>
    </default>

    <worldbody>
        <light pos="0 0 1"/>
        <light pos="0 -0.2 1" dir="0 0.2 -0.8" directional="true"/>
        <geom name="floor" size="0 0 0.05" type="plane" material="groundplane" pos="0 0 -0.5" friction="0.1"  conaffinity="1" condim="3"/>
        <!--        <geom conaffinity="1" condim="3" material="MatPlane" name="floor" pos="0 0 -0.500" rgba="0.8 0.9 0.8 1" size="10 10 10" type="plane" friction="0.1"/>-->

        <body name="quaid" pos="2 0 0" euler="0 0 0">
            <!--   this will make it fall down -->
            <freejoint/>
            <geom name="fuselage" type="mesh" mesh="fuselage" euler="0 0 90" />
<!--            <camera name="tracking_cam" mode="trackcom" pos="0 0 -50" target="quaid" />-->
            <site name="imu" size="0.01" pos="-0.85 -0.3 0.5"/>
            <body name="front" pos="0 0 0" euler="0 0 90">
                <geom name="pelvis_front" type="mesh" mesh="pelvis" />

                <body name="leg_fl">
                    <geom name="servos_mount_fl" type="mesh" mesh="left_servo_mount"  />
                    <geom name="servo1_fl" type="mesh" mesh="left_thigh_servo" rgba="0 0 0 1"/>
                    <body name="thigh1_fl" pos="0 0 0">
                        <joint name="thigh_joint1_fl" type="hinge" pos="0.2 -0.15 0.515" axis="1 0 0" range="0.0 45.0" damping="10" limited="true" />
                        <geom name="thigh_horn_fl1" type="mesh" mesh="left_thigh_horn" rgba="0.137 0.408 0.8 1" />
                        <body name="thigh_link_b1_fl">
                            <joint name="thigh_link_joint1_fl" type="hinge" pos="0.2 -0.16 0.685" axis="1 0 0" damping="0.05" limited="false" />
                            <geom name="thigh_link1_fl" type="mesh" mesh="left_thigh_link"  rgba="0.137 0.408 0.8 1"  />
                        </body>
                    </body>

                    <body name="thigh_limb_b1_fl">
                        <joint name="thigh_limb_joint1_fl" type="hinge" pos="0.2 0.015 0.515" axis="1 0 0" damping="0.05" limited="false" />
                        <geom name="thigh_limb1_fl" type="mesh" mesh="left_thigh"  rgba="0.137 0.408 0.8 1"  />
                    </body>

                    <geom name="servo2_fl" type="mesh" mesh="left_knee_servo" rgba="0 0 0 1" />
                    <body name="knee_fl" >
                        <joint name="knee1_joint_fl" type="hinge" pos="0.2 0.015 0.515" axis="1 0 0" range="-25 25.0" damping="10" limited="true" />
                        <geom name="knee_horn1_fl" type="mesh" mesh="left_knee_horn" />
                        <body name="knee_link_b1_fl">
                            <joint name="knee1_link_joint_fl" type="hinge" pos="0.27 0.16 0.60" axis="1 0 0" damping="0.05" limited="false" />
                            <geom name="knee_link1_fl" type="mesh" mesh="left_knee_link" />
                            <body name="calf1_body_fl">
                                <joint name="calf1_joint_fl" type="hinge" pos="0.27 0.157 0.1" axis="1 0 0" damping="0.05" limited="false" />
                                <geom name="calf1_fl" type="mesh" mesh="left_calf" />
                            </body>
                        </body>
                    </body>
                </body>

                <body name="leg_fr" >
                    <geom name="servos_mount_fr" type="mesh" mesh="right_servo_mount" />
                    <geom name="servo1_fr" type="mesh" mesh="right_thigh_servo" rgba="0 0 0 1"/>
                    <body name="thigh1_fr" pos="0 0 0">
                        <joint name="thigh_joint1_fr" type="hinge" pos="-0.85 -0.15 0.515" axis="-1 0 0" range="-45.0 0" damping="10" limited="true" />
                        <geom name="thigh_horn_fr1" type="mesh" mesh="right_thigh_horn"  rgba="0.137 0.408 0.8 1" />
                        <body name="thigh_link_b1_fr">
                            <joint name="thigh_link_joint1_fr" type="hinge" pos="-0.85 -0.16 0.685" axis="-1 0 0" damping="0.05" limited="false" />
                            <geom name="thigh_link1_fr" type="mesh" mesh="right_thigh_link"  rgba="0.137 0.408 0.8 1" />
                        </body>
                    </body>

                    <body name="thigh_limb_b1_fr">
                        <joint name="thigh_limb_joint1_fr" type="hinge" pos="-0.85 0.015 0.515" axis="-1 0 0" damping="0.05" limited="false" />
                        <geom name="thigh_limb1_fr" type="mesh" mesh="right_thigh"  rgba="0.137 0.408 0.8 1" />
                    </body>

                    <geom name="servo2_fr" type="mesh" mesh="right_knee_servo" rgba="0 0 0 1" />
                    <body name="knee_fr" >
                        <joint name="knee1_joint_fr" type="hinge" pos="-0.85 0.015 0.515" axis="-1 0 0" range="-25.0 25.0" damping="10" limited="true" />
                        <geom name="knee_horn1_fr" type="mesh" mesh="right_knee_horn" />
                        <body name="knee_link_b1_fr">
                            <joint name="knee1_link_joint_fr" type="hinge" pos="-0.9 0.16 0.60" axis="-1 0 0" damping="0.05" limited="false" />
                            <geom name="knee_link1_fr" type="mesh" mesh="right_knee_link" />
                            <body name="calf1_body_fr">
                                <joint name="calf1_joint_fr" type="hinge" pos="-0.9 0.157 0.1" axis="-1 0 0" damping="0.05" limited="false" />
                                <geom name="calf1_fr" type="mesh" mesh="right_calf"  />
                            </body>
                        </body>
                    </body>
                </body>
            </body>




            <body name="back" pos="-1.70 0 0" euler="0 0 90">
                <geom name="pelvis_back" type="mesh" mesh="pelvis" />

                <body name="leg_bl">
                    <geom name="servos_mount_bl" type="mesh" mesh="left_servo_mount"  />
                    <geom name="servo1_bl" type="mesh" mesh="left_thigh_servo" rgba="0 0 0 1"/>
                    <body name="thigh1_bl" pos="0 0 0">
                        <joint name="thigh_joint1_bl" type="hinge" pos="0.2 -0.15 0.515" axis="1 0 0" range="0 45.0" damping="10" limited="true" />
                        <geom name="thigh_horn_bl1" type="mesh" mesh="left_thigh_horn" rgba="0.137 0.408 0.8 1" />
                        <body name="thigh_link_b1_bl">
                            <joint name="thigh_link_joint1_bl" type="hinge" pos="0.2 -0.16 0.685" axis="1 0 0" damping="0.05" limited="false" />
                            <geom name="thigh_link1_bl" type="mesh" mesh="left_thigh_link"  rgba="0.137 0.408 0.8 1"  />
                        </body>
                    </body>

                    <body name="thigh_limb_b1_bl">
                        <joint name="thigh_limb_joint1_bl" type="hinge" pos="0.2 0.015 0.515" axis="1 0 0" damping="0.05" limited="false" />
                        <geom name="thigh_limb1_bl" type="mesh" mesh="left_thigh"  rgba="0.137 0.408 0.8 1"  />
                    </body>

                    <geom name="servo2_bl" type="mesh" mesh="left_knee_servo" rgba="0 0 0 1" />
                    <body name="knee_bl" >
                        <joint name="knee1_joint_bl" type="hinge" pos="0.2 0.015 0.515" axis="1 0 0" range="-25.0 25.0" damping="10" limited="true" />
                        <geom name="knee_horn1_bl" type="mesh" mesh="left_knee_horn" />
                        <body name="knee_link_b1_bl">
                            <joint name="knee1_link_joint_bl" type="hinge" pos="0.27 0.16 0.60" axis="1 0 0" damping="0.05" limited="false" />
                            <geom name="knee_link1_bl" type="mesh" mesh="left_knee_link" />
                            <body name="calf1_body_bl">
                                <joint name="calf1_joint_bl" type="hinge" pos="0.27 0.157 0.1" axis="1 0 0" damping="0.05" limited="false" />
                                <geom name="calf1_bl" type="mesh" mesh="left_calf" />
                            </body>
                        </body>
                    </body>
                </body>

                <body name="leg_br" >
                    <geom name="servos_mount_br" type="mesh" mesh="right_servo_mount" />
                    <geom name="servo1_br" type="mesh" mesh="right_thigh_servo" rgba="0 0 0 1"/>
                    <body name="thigh1_br" pos="0 0 0">
                        <joint name="thigh_joint1_br" type="hinge" pos="-0.85 -0.15 0.515" axis="-1 0 0" range="-45.0 0" damping="10" limited="true" />
                        <geom name="thigh_horn_br1" type="mesh" mesh="right_thigh_horn"  rgba="0.137 0.408 0.8 1" />
                        <body name="thigh_link_b1_br">
                            <joint name="thigh_link_joint1_br" type="hinge" pos="-0.85 -0.16 0.685" axis="-1 0 0" damping="0.05" limited="false" />
                            <geom name="thigh_link1_br" type="mesh" mesh="right_thigh_link"  rgba="0.137 0.408 0.8 1" />
                        </body>
                    </body>

                    <body name="thigh_limb_b1_br">
                        <joint name="thigh_limb_joint1_br" type="hinge" pos="-0.85 0.015 0.515" axis="-1 0 0" damping="0.05" limited="false" />
                        <geom name="thigh_limb1_br" type="mesh" mesh="right_thigh"  rgba="0.137 0.408 0.8 1" />
                    </body>

                    <geom name="servo2_br" type="mesh" mesh="right_knee_servo" rgba="0 0 0 1" />
                    <body name="knee_br" >
                        <joint name="knee1_joint_br" type="hinge" pos="-0.85 0.015 0.515" axis="-1 0 0" range="-25.0 25.0" damping="10" limited="true" />
                        <geom name="knee_horn1_br" type="mesh" mesh="right_knee_horn" />
                        <body name="knee_link_b1_br">
                            <joint name="knee1_link_joint_br" type="hinge" pos="-0.9 0.16 0.60" axis="-1 0 0" damping="0.05" limited="false" />
                            <geom name="knee_link1_br" type="mesh" mesh="right_knee_link" />
                            <body name="calf1_body_br">
                                <joint name="calf1_joint_br" type="hinge" pos="-0.9 0.157 0.1" axis="-1 0 0" damping="0.05" limited="false" />
                                <geom name="calf1_br" type="mesh" mesh="right_calf"  />
                            </body>
                        </body>
                    </body>
                </body>
            </body>



        </body>


        <body name="frame_reference" pos="0 0 0" mocap="true">
            <geom type="cylinder" size="0.025 0.5" rgba="0 0 .9 1" />
            <geom type="cylinder" size="0.025 0.25" rgba=".9 0 0 1" euler="0 90 0" pos="0.25 0 .5"/>
            <geom type="cylinder" size="0.025 0.25" rgba="0 .9 0 1" euler="90 0 0" pos="0.0 0.25 .5"/>
        </body>

        <body name="marker" pos="0 0 1" mocap="true">
            <geom type="cylinder" size="0.05 0.5" rgba="0 0 .9 1" />
            <geom type="cylinder" size="0.05 0.25" rgba=".9 0 0 1" euler="0 90 0" pos="0.25 0 .5"/>
            <geom type="cylinder" size="0.05 0.25" rgba="0 .9 0 1" euler="90 0 0" pos="0.0 0.25 .5"/>
        </body>

    </worldbody>

    <equality>
        <!-- These could also be equality/joint -->
        <connect body1="thigh_link_b1_fl" body2="thigh_limb_b1_fl" anchor="0.24 0.09 0.665"/>
        <connect body1="calf1_body_fl" body2="thigh_limb_b1_fl" anchor="0.28 0.01 0.015"/>
        <connect body1="thigh_link_b1_fr" body2="thigh_limb_b1_fr" anchor="-0.85 0.09 0.665"/>
        <connect body1="calf1_body_fr" body2="thigh_limb_b1_fr" anchor="-0.9 0.01 0.015"/>

        <connect body1="thigh_link_b1_bl" body2="thigh_limb_b1_bl" anchor="0.24 0.09 0.665"/>
        <connect body1="calf1_body_bl" body2="thigh_limb_b1_bl" anchor="0.28 0.01 0.015"/>
        <connect body1="thigh_link_b1_br" body2="thigh_limb_b1_br" anchor="-0.85 0.09 0.665"/>
        <connect body1="calf1_body_br" body2="thigh_limb_b1_br" anchor="-0.9 0.01 0.015"/>
    </equality>

    <actuator>
        <position joint="knee1_joint_fl" ctrlrange="-1.0 1.0"
                  kp="1000"
                  ctrllimited="true" name="knee_servo1_fl"/>
        <velocity joint="knee1_joint_fl" kv="100" name="knee1_velocity_fl" />

        <position joint="thigh_joint1_fl" ctrlrange="0 1.0"
                  kp="1000"
                  ctrllimited="true" name="thigh_servo1_fl"/>
        <velocity joint="thigh_joint1_fl" kv="100" name="thigh1_velocity_fl" />

        <position joint="knee1_joint_fr" ctrlrange="-1.0 1.0"
                  kp="1000"
                  ctrllimited="true" name="knee_servo1_fr"/>
        <velocity joint="knee1_joint_fr" kv="100" name="knee1_velocity_fr" />

        <position joint="thigh_joint1_fr" ctrlrange="-1.0 0"
                  kp="1000"
                  ctrllimited="true" name="thigh_servo1_fr"/>
        <velocity joint="thigh_joint1_fr" kv="100" name="thigh1_velocity_fr" />


        <position joint="knee1_joint_bl" ctrlrange="-1.0 1.0"
                  kp="1000"
                  ctrllimited="true" name="knee_servo1_bl"/>
        <velocity joint="knee1_joint_bl" kv="100" name="knee1_velocity_bl" />

        <position joint="thigh_joint1_bl" ctrlrange="0 1.0"
                  kp="1000"
                  ctrllimited="true" name="thigh_servo1_bl"/>
        <velocity joint="thigh_joint1_bl" kv="100" name="thigh1_velocity_bl" />

        <position joint="knee1_joint_br" ctrlrange="-1.0 1.0"
                  kp="1000"
                  ctrllimited="true" name="knee_servo1_br"/>
        <velocity joint="knee1_joint_br" kv="100" name="knee1_velocity_br" />

        <position joint="thigh_joint1_br" ctrlrange="-1.0 0"
                  kp="1000"
                  ctrllimited="true" name="thigh_servo1_br"/>
        <velocity joint="thigh_joint1_br" kv="100" name="thigh1_velocity_br" />
    </actuator>

    <sensor>
        <framequat name="orientation" objtype="site" objname="imu" noise="0.0"/>
        <framepos name="position" objtype="site" objname="imu" noise="0.0"/>
        <gyro name="gyro" site="imu" /> <!--  noise="5e-4" cutoff="34.9" -->
        <accelerometer name="acceleration" site="imu" /> <!-- noise="1e-2" cutoff="157" -->
        <magnetometer name="magnetometer" site="imu"/>
    </sensor>
</mujoco>