<mujoco model="quaid">
    <compiler inertiafromgeom="true" angle="degree" coordinate="local"/>
    <option timestep="0.005" gravity="0 0 -9.81" iterations="20" integrator="RK4" >
        <!-- this was deprecated in 3.14 - you need to add your own noise now -->
<!--        <flag sensornoise="enable" />-->
    </option>

    <asset>
        <texture type="skybox" builtin="gradient" rgb1="0.3 0.5 0.7" rgb2="0 0 0" width="512" height="3072"/>
        <texture type="2d" name="groundplane" builtin="checker" mark="edge" rgb1="0.2 0.3 0.4"
                 rgb2="0.1 0.2 0.3" markrgb="0.8 0.8 0.8" width="300" height="300"/>
        <material name="groundplane" texture="groundplane" texuniform="true" texrepeat="5 5" reflectance="0.2"/>

        <texture file="../material/lightwood.png" type="cube" name="light-wood" />
        <material name="light-wood-mat" texture="light-wood" texrepeat="3 3" specular="0.4" shininess="0.1" />

        <mesh file="left_calf.stl" scale="0.01 0.01 0.01" />
        <mesh file="left_knee_horn.stl" scale="0.01 0.01 0.01" />
        <mesh file="left_knee_link.stl" scale="0.01 0.01 0.01" />
        <mesh file="left_thigh_servo.stl" scale="0.01 0.01 0.01" />
        <mesh file="left_knee_servo.stl" scale="0.01 0.01 0.01" />
        <mesh file="left_servo_mount.stl" scale="0.01 0.01 0.01" />
        <mesh file="left_thigh.stl" scale="0.01 0.01 0.01" />
        <mesh file="left_thigh_horn.stl" scale="0.01 0.01 0.01" />
        <mesh file="left_thigh_link.stl" scale="0.01 0.01 0.01" />
        <mesh file="right_calf.stl" scale="0.01 0.01 0.01" />
        <mesh file="right_knee_horn.stl" scale="0.01 0.01 0.01" />
        <mesh file="right_knee_link.stl" scale="0.01 0.01 0.01" />
        <mesh file="right_thigh_servo.stl" scale="0.01 0.01 0.01" />
        <mesh file="right_knee_servo.stl" scale="0.01 0.01 0.01" />
        <mesh file="right_servo_mount.stl" scale="0.01 0.01 0.01" />
        <mesh file="right_thigh.stl" scale="0.01 0.01 0.01" />
        <mesh file="right_thigh_horn.stl" scale="0.01 0.01 0.01" />
        <mesh file="right_thigh_link.stl" scale="0.01 0.01 0.01" />
        <mesh file="top_link.stl" scale="0.01 0.01 0.01" />
        <mesh file="bottom_link.stl" scale="0.01 0.01 0.01" />
        <mesh file="fuselage.stl" scale="0.01 0.01 0.01" />

        <mesh file="../scene/scene_incline.stl" scale="0.02 0.02 0.01" />
    </asset>

    <default>
        <joint armature="1" damping="1" limited="true"/>
        <geom conaffinity="0" condim="3" density="150.0" margin="0.002" /> <!-- rgba="0.8 0.6 0.4 1" -->
        <!--         <geom friction=".1 .1 .1" density="300" margin="0.002" condim="1" contype="0" conaffinity="0"/>-->

        <default class="collision">
            <geom contype="1" group="3" type="capsule"/>
            <default class="collision-left">
                <geom contype="2" conaffinity="4"/>
            </default>
            <default class="collision-right">
                <geom contype="4" conaffinity="2"/>
            </default>
        </default>
    </default>

    <worldbody>
        <light pos="0 0 1"/>
        <light pos="0 -0.2 1" dir="0 0.2 -0.8" directional="true"/>
        <geom name="floor" size="0 0 0.05" type="plane" material="groundplane" pos="0 0 -0.5" friction="0.1"  conaffinity="1" condim="3"/>
        <!--        <geom conaffinity="1" condim="3" material="MatPlane" name="floor" pos="0 0 -0.500" rgba="0.8 0.9 0.8 1" size="10 10 10" type="plane" friction="0.1"/>-->

        <body name="quaid" pos="2 0 0" euler="0 0 0">
            <!--   this will make it fall down -->
            <freejoint />
            <geom name="fuselage" type="mesh" mesh="fuselage" euler="0 0 90" />
<!--            <camera name="tracking_cam" mode="trackcom" pos="0 0 -50" target="quaid" />-->
            <site name="imu" size="0.01" pos="-0.95 -0.34 -0.08"/>
            <body name="front" pos="0 0 0" euler="0 0 90">
                <geom name="bottom_link_front" type="mesh" mesh="bottom_link" />
                <geom name="top_link_front" type="mesh" mesh="top_link" />

                <body name="leg_fl">
                    <geom name="servos_mount_fl" type="mesh" mesh="left_servo_mount"  />
                    <geom name="servo1_fl" type="mesh" mesh="left_thigh_servo" rgba="0 0 0 1"/>
                    <body name="thigh1_fl" pos="0 0 0">
                        <joint name="thigh_joint1_fl" type="hinge" pos="0.100 -0.085 0.11" axis="1 0 0" range="0.0 45.0" damping="10" limited="true" />
                        <geom name="thigh_horn_fl1" type="mesh" mesh="left_thigh_horn" rgba="0.137 0.408 0.8 1" />
                        <body name="thigh_link_b1_fl">
                            <joint name="thigh_link_joint1_fl" type="hinge" pos="0.07 -0.085 0.28" axis="1 0 0" damping="0.05" limited="false" />
                            <geom name="thigh_link1_fl" type="mesh" mesh="left_thigh_link"  rgba="0.137 0.408 0.8 1"  />
                        </body>
                    </body>

                    <body name="thigh_limb_b1_fl">
                        <joint name="thigh_limb_joint1_fl" type="hinge" pos="0.1 0.085 0.11" axis="1 0 0" damping="0.05" limited="false" />
                        <geom name="thigh_limb1_fl" type="mesh" mesh="left_thigh"  rgba="0.137 0.408 0.8 1"  />
                    </body>

                    <geom name="servo2_fl" type="mesh" mesh="left_knee_servo" rgba="0 0 0 1" />
                    <body name="knee_fl" >
                        <joint name="knee1_joint_fl" type="hinge" pos="0.1 0.085 0.11" axis="1 0 0" range="-25 25.0" damping="10" limited="true"  />
                        <geom name="knee_horn1_fl" type="mesh" mesh="left_knee_horn" />
                        <body name="knee_link_b1_fl">
                            <joint name="knee1_link_joint_fl" type="hinge" pos="0.1 0.225 0.205" axis="1 0 0" damping="0.05" limited="false" />
                            <geom name="knee_link1_fl" type="mesh" mesh="left_knee_link" />
                            <body name="calf1_body_fl">
                                <joint name="calf1_joint_fl" type="hinge" pos="0.15 0.228 -0.29" axis="1 0 0" damping="5" limited="false" />
                                <geom name="calf1_fl" type="mesh" mesh="left_calf" />
                            </body>
                        </body>
                    </body>
                </body>

                <body name="leg_fr" pos="-0.78 0 0" >
                    <geom name="servos_mount_fr" type="mesh" mesh="right_servo_mount"  />
                    <geom name="servo1_fr" type="mesh" mesh="right_thigh_servo" rgba="0 0 0 1"/>
                    <body name="thigh1_fr" pos="0 0 0">
                        <joint name="thigh_joint1_fr" type="hinge" pos="-0.00 -0.085 0.11" axis="-1 0 0" range="-45.0 0" damping="10" limited="true" />
                        <geom name="thigh_horn_fr1" type="mesh" mesh="right_thigh_horn"  rgba="0.137 0.408 0.8 1" />
                        <body name="thigh_link_b1_fr">
                            <joint name="thigh_link_joint1_fr" type="hinge" pos="0.0 -0.085 0.28" axis="-1 0 0" damping="0.05" limited="false" />
                            <geom name="thigh_link1_fr" type="mesh" mesh="right_thigh_link"  rgba="0.137 0.408 0.8 1" />
                        </body>
                    </body>

                    <body name="thigh_limb_b1_fr">
                        <joint name="thigh_limb_joint1_fr" type="hinge" pos="0.0 0.085 0.11" axis="-1 0 0" damping="0.05" limited="false" />
                        <geom name="thigh_limb1_fr" type="mesh" mesh="right_thigh"  rgba="0.137 0.408 0.8 1" />
                    </body>

                    <geom name="servo2_fr" type="mesh" mesh="right_knee_servo" rgba="0 0 0 1" />
                    <body name="knee_fr" >
                        <joint name="knee1_joint_fr" type="hinge" pos="-0.1 0.085 0.11" axis="-1 0 0" range="-25.0 25.0" damping="10" limited="true" />
                        <geom name="knee_horn1_fr" type="mesh" mesh="right_knee_horn" />
                        <body name="knee_link_b1_fr">
                            <joint name="knee1_link_joint_fr" type="hinge" pos="-0.1 0.225 0.205" axis="-1 0 0" damping="0.05" limited="false" />
                            <geom name="knee_link1_fr" type="mesh" mesh="right_knee_link" />
                            <body name="calf1_body_fr">
                                <joint name="calf1_joint_fr" type="hinge" pos="-0.15 0.228 -0.29" axis="-1 0 0" damping="5" limited="false" />
                                <geom name="calf1_fr" type="mesh" mesh="right_calf"  />
                            </body>
                        </body>
                    </body>
                </body>
            </body>


            <body name="back" pos="-1.83 0 0" euler="0 0 90">
                <geom name="bottom_link_back" type="mesh" mesh="bottom_link" />
                <geom name="top_link_back" type="mesh" mesh="top_link" />

                <body name="leg_bl">
                    <geom name="servos_mount_bl" type="mesh" mesh="left_servo_mount"  />
                    <geom name="servo1_bl" type="mesh" mesh="left_thigh_servo" rgba="0 0 0 1"/>
                    <body name="thigh1_bl" pos="0 0 0">
                        <joint name="thigh_joint1_bl" type="hinge" pos="0.100 -0.085 0.11" axis="1 0 0" range="0.0 45.0" damping="10" limited="true" />
                        <geom name="thigh_horn_bl1" type="mesh" mesh="left_thigh_horn" rgba="0.137 0.408 0.8 1" />
                        <body name="thigh_link_b1_bl">
                            <joint name="thigh_link_joint1_bl" type="hinge" pos="0.07 -0.085 0.28" axis="1 0 0" damping="0.05" limited="false" />
                            <geom name="thigh_link1_bl" type="mesh" mesh="left_thigh_link"  rgba="0.137 0.408 0.8 1"  />
                        </body>
                    </body>

                    <body name="thigh_limb_b1_bl">
                        <joint name="thigh_limb_joint1_bl" type="hinge" pos="0.1 0.085 0.11" axis="1 0 0" damping="0.05" limited="false" />
                        <geom name="thigh_limb1_bl" type="mesh" mesh="left_thigh"  rgba="0.137 0.408 0.8 1"  />
                    </body>

                    <geom name="servo2_bl" type="mesh" mesh="left_knee_servo" rgba="0 0 0 1" />
                    <body name="knee_bl" >
                        <joint name="knee1_joint_bl" type="hinge" pos="0.1 0.085 0.11" axis="1 0 0" range="-25 25.0" damping="10" limited="true" />
                        <geom name="knee_horn1_bl" type="mesh" mesh="left_knee_horn" />
                        <body name="knee_link_b1_bl">
                            <joint name="knee1_link_joint_bl" type="hinge" pos="0.1 0.225 0.205" axis="1 0 0" damping="0.05" limited="false" />
                            <geom name="knee_link1_bl" type="mesh" mesh="left_knee_link" />
                            <body name="calf1_body_bl">
                                <joint name="calf1_joint_bl" type="hinge" pos="0.15 0.228 -0.29" axis="1 0 0" damping="5" limited="false" />
                                <geom name="calf1_bl" type="mesh" mesh="left_calf" />
                            </body>
                        </body>
                    </body>
                </body>

                <body name="leg_br" pos="-0.78 0 0" >
                    <geom name="servos_mount_br" type="mesh" mesh="right_servo_mount"  />
                    <geom name="servo1_br" type="mesh" mesh="right_thigh_servo" rgba="0 0 0 1"/>
                    <body name="thigh1_br" pos="0 0 0">
                        <joint name="thigh_joint1_br" type="hinge" pos="-0.00 -0.085 0.11" axis="-1 0 0" range="-45.0 0" damping="10" limited="true" />
                        <geom name="thigh_horn_br1" type="mesh" mesh="right_thigh_horn"  rgba="0.137 0.408 0.8 1" />
                        <body name="thigh_link_b1_br">
                            <joint name="thigh_link_joint1_br" type="hinge" pos="0.0 -0.085 0.28" axis="-1 0 0" damping="0.05" limited="false" />
                            <geom name="thigh_link1_br" type="mesh" mesh="right_thigh_link"  rgba="0.137 0.408 0.8 1" />
                        </body>
                    </body>

                    <body name="thigh_limb_b1_br">
                        <joint name="thigh_limb_joint1_br" type="hinge" pos="0.0 0.085 0.11" axis="-1 0 0" damping="0.05" limited="false" />
                        <geom name="thigh_limb1_br" type="mesh" mesh="right_thigh"  rgba="0.137 0.408 0.8 1" />
                    </body>

                    <geom name="servo2_br" type="mesh" mesh="right_knee_servo" rgba="0 0 0 1" />
                    <body name="knee_br" >
                        <joint name="knee1_joint_br" type="hinge" pos="-0.1 0.085 0.11" axis="-1 0 0" range="-25.0 25.0" damping="10" limited="true" />
                        <geom name="knee_horn1_br" type="mesh" mesh="right_knee_horn" />
                        <body name="knee_link_b1_br">
                            <joint name="knee1_link_joint_br" type="hinge" pos="-0.1 0.225 0.205" axis="-1 0 0" damping="0.05" limited="false" />
                            <geom name="knee_link1_br" type="mesh" mesh="right_knee_link" />
                            <body name="calf1_body_br">
                                <joint name="calf1_joint_br" type="hinge" pos="-0.15 0.228 -0.29" axis="-1 0 0" damping="5" limited="false" />
                                <geom name="calf1_br" type="mesh" mesh="right_calf"  />
                            </body>
                        </body>
                    </body>
                </body>

            </body>


        </body>


        <body name="frame_reference" pos="0.85 -0.34 0" mocap="true">
            <geom type="cylinder" size="0.025 0.5" rgba="0 0 .9 1" />
            <geom type="cylinder" size="0.025 0.25" rgba=".9 0 0 1" euler="0 90 0" pos="0.25 0 .5"/>
            <geom type="cylinder" size="0.025 0.25" rgba="0 .9 0 1" euler="90 0 0" pos="0.0 0.25 .5"/>
        </body>

        <body name="marker" pos="0.85 -0.34 1" mocap="true">
            <geom type="cylinder" size="0.05 0.5" rgba="0 0 .9 1" />
            <geom type="cylinder" size="0.05 0.25" rgba=".9 0 0 1" euler="0 90 0" pos="0.25 0 .5"/>
            <geom type="cylinder" size="0.05 0.25" rgba="0 .9 0 1" euler="90 0 0" pos="0.0 0.25 .5"/>
        </body>


        <body name="incline" pos="0 0 -0.50" euler="0 0 0" mocap="true">
            <geom name="incline" type="mesh" mesh="scene_incline"  conaffinity="1" condim="3" material="light-wood-mat" />
        </body>

    </worldbody>

    <equality>
        <!-- These could also be equality/joint -->
        <connect body1="thigh_link_b1_fl" body2="thigh_limb_b1_fl" anchor="0.225 0.164 0.26"/>
        <connect body1="calf1_body_fl" body2="thigh_limb_b1_fl" anchor="0.25 0.085 -0.39"/>
        <connect body1="thigh_link_b1_fr" body2="thigh_limb_b1_fr" anchor="-0.1 0.164 0.26"/>
        <connect body1="calf1_body_fr" body2="thigh_limb_b1_fr" anchor="-0.13 0.085 -0.39"/>

        <connect body1="thigh_link_b1_bl" body2="thigh_limb_b1_bl" anchor="0.225 0.164 0.26"/>
        <connect body1="calf1_body_bl" body2="thigh_limb_b1_bl" anchor="0.25 0.085 -0.39"/>
        <connect body1="thigh_link_b1_br" body2="thigh_limb_b1_br" anchor="-0.1 0.164 0.26"/>
        <connect body1="calf1_body_br" body2="thigh_limb_b1_br" anchor="-0.13 0.085 -0.39"/>
    </equality>

    <actuator>
        <position joint="knee1_joint_fl" ctrlrange="-0.5 0.5"
                  kp="200"
                  ctrllimited="true" name="knee_servo1_fl"/>
        <velocity joint="knee1_joint_fl" kv="1" name="knee1_velocity_fl" />

        <position joint="thigh_joint1_fl" ctrlrange="0 0.60"
                  kp="200"
                  ctrllimited="true" name="thigh_servo1_fl"/>
        <velocity joint="thigh_joint1_fl" kv="1" name="thigh1_velocity_fl" />

        <position joint="knee1_joint_fr" ctrlrange="-0.5 0.5"
                  kp="200"
                  ctrllimited="true" name="knee_servo1_fr"/>
        <velocity joint="knee1_joint_fr" kv="1" name="knee1_velocity_fr" />

        <position joint="thigh_joint1_fr" ctrlrange="-0.6 0"
                  kp="200"
                  ctrllimited="true" name="thigh_servo1_fr"/>
        <velocity joint="thigh_joint1_fr" kv="1" name="thigh1_velocity_fr" />



        <position joint="knee1_joint_bl" ctrlrange="-0.5 0.5"
                  kp="200"
                  ctrllimited="true" name="knee_servo1_bl"/>
        <velocity joint="knee1_joint_bl" kv="1" name="knee1_velocity_bl" />

        <position joint="thigh_joint1_bl" ctrlrange="0 0.60"
                  kp="200"
                  ctrllimited="true" name="thigh_servo1_bl"/>
        <velocity joint="thigh_joint1_bl" kv="1" name="thigh1_velocity_bl" />

        <position joint="knee1_joint_br" ctrlrange="-0.5 0.5"
                  kp="200"
                  ctrllimited="true" name="knee_servo1_br"/>
        <velocity joint="knee1_joint_br" kv="1" name="knee1_velocity_br" />

        <position joint="thigh_joint1_br" ctrlrange="-0.60 0"
                  kp="200"
                  ctrllimited="true" name="thigh_servo1_br"/>
        <velocity joint="thigh_joint1_br" kv="1" name="thigh1_velocity_br" />

    </actuator>

    <sensor>
        <framequat name="orientation" objtype="site" objname="imu" noise="0.05"/>
        <framepos name="position" objtype="site" objname="imu" noise="0.05"/>

        <!--
        <actuatorfrc name="knee_fl_torque" actuator="knee_servo1_fl"/>
        <actuatorfrc name="thigh_fl_torque" actuator="thigh_servo1_fl"/>
        <actuatorfrc name="knee_fr_torque" actuator="knee_servo1_fr"/>
        <actuatorfrc name="thigh_fr_torque" actuator="thigh_servo1_fr"/>

        <actuatorfrc name="knee_bl_torque" actuator="knee_servo1_bl"/>
        <actuatorfrc name="thigh_bl_torque" actuator="thigh_servo1_bl"/>
        <actuatorfrc name="knee_br_torque" actuator="knee_servo1_br"/>
        <actuatorfrc name="thigh_br_torque" actuator="thigh_servo1_br"/>
        -->

        <!-- these should measure the force at joint -->
        <jointactuatorfrc name="knee_fl_torque" joint="knee1_joint_fl" />
        <jointactuatorfrc name="thigh_fl_torque" joint="thigh_joint1_fl" />
        <jointactuatorfrc name="knee_fr_torque" joint="knee1_joint_fr" />
        <jointactuatorfrc name="thigh_fr_torque" joint="thigh_joint1_fr" />

        <jointactuatorfrc name="knee_bl_torque" joint="knee1_joint_bl" />
        <jointactuatorfrc name="thigh_bl_torque" joint="thigh_joint1_bl" />
        <jointactuatorfrc name="knee_br_torque" joint="knee1_joint_br" />
        <jointactuatorfrc name="thigh_br_torque" joint="thigh_joint1_br" />
        <!-- -->
        <accelerometer name="acceleration" site="imu" /> <!-- noise="1e-2" cutoff="157" -->
        <gyro name="gyro" site="imu" /> <!--  noise="5e-4" cutoff="34.9" -->
        <magnetometer name="magnetometer" site="imu"/>
    </sensor>
</mujoco>
